<?xm1 version="1.0"?> 
<robot name="planar2">
    <link name="base_link"></link> 
    <link name="link1" /> 
    <link name="link2" /> 
    <link name="end" />
    <joint name="joint1" type="continuous">
        <parent link="base_link" /> 
        <child link="link1" /> 
        <axis xyz="0 0 1" />
    </joint>
    <joint name="joint2" type="continuous">
        <parent link="link1" /> 
        <child link="link2" /> 
        <origin xyz="1 0 0" /> 
        <axis xyz="0 0 1" />
    </joint>
    <joint name="endeffectornub" type="fixed">
        <parent link="link2" /> 
        <child link="end" /> 
        <origin xyz="1 0 0" />
    </joint>
</robot>